Workbook

Sheet Start
A1: AVAB – masterkalkyl för budgetkalkylator
A4: Syfte
A5: Excel-filen är intern master för kalkylatorn. Varje område har en egen flik. Sporthall använder startvärdena från den uppladdade HTML-kalkylatorn. Simhall, Konferens, Restaurang och Gym är nu förifyllda med tydligt märkta TESTSTARTVÄRDEN så att hela flödet kan provas innan ni ersätter dem med skarpa kalkyler.
A9: Arbetsflöde | B9: Vad ni gör
A10: 1. Fyll delar | B10: Lägg interna komponenter, mängder, inköpspris och arbetstid i områdets komponenttabell.
A11: 2. Koppla Paket-ID | B11: Varje intern del kopplas till ett Paket-ID, t.ex. basePackage:dsp.
A12: 3. Kontrollera kalkylpris | B12: Excel summerar internt kalkylpris och timmar per Paket-ID.
A13: 4. Godkänn för webb | B13: Sätt "Använd intern kalkyl?" = Ja först när paketet är komplett och kontrollerat.
A14: 5. Exportera | B14: Bladet Webbexport innehåller endast webbens summerade data och kan senare skrivas till JSON av ett script.
A17: Områdesflik | B17: Status | C17: Kommentar
A18: Sporthall | B18: Aktiv/Testklar | C18: HTML-värden bevarade. Interna startdelar reproducerar startpriserna.
A19: Simhall | B19: Testklar | C19: TESTSTARTVÄRDEN inlagda – byt innan skarp publicering.
A20: Konferens | B20: Testklar | C20: TESTSTARTVÄRDEN inlagda – byt innan skarp publicering.
A21: Restaurang | B21: Testklar | C21: TESTSTARTVÄRDEN inlagda – byt innan skarp publicering.
A22: Gym | B22: Testklar | C22: TESTSTARTVÄRDEN inlagda – byt innan skarp publicering.

Sheet Inställningar
A1: Globala inställningar
A4: Parameter | B4: Värde | C4: Enhet | D4: Kommentar
A5: Standard timpris | B5: 850 | C5: kr/h | D5: Fylls av AVAB. Används som standard i komponentrader.
A6: Standard påslag | B6: 0.15 | C6: % | D6: Fylls av AVAB. Kan överstyras per komponentrad.
A7: Moms | B7: 0.25 | C7: % | D7: Webbkalkylatorn visar budget exklusive moms.
A8: Version | B8: 2026-08-13 | D8: Första masterfilen baserad på uppladdad HTML-kalkylator.
A9: Valuta | B9: SEK | D9: Exportpriser anges i SEK.
A10: Teststartvärden | B10: Ja | D10: Övriga områden innehåller testvärden för att kalkylflödet ska kunna provas. Byt innan skarp publicering.
A11: Princip | B11: Sporthall från HTML | D11: Sporthallens publicerade startvärden är hämtade från den uppladdade kalkylatorsidan; interna delrader är startfördelningar som reproducerar dessa totalsummor.

Sheet Sporthall
A1: Sporthall – kalkylmaster
A3: Aktiv/Testklar – startvärdena kommer från den uppladdade HTML-kalkylatorn. Interna startdelar är generiska testfördelningar som reproducerar respektive webbpris. Byt dem mot verkliga komponenter när ni är redo.
A6: Publicera | B6: Grupp | C6: Nyckel | D6: Paket-ID | E6: Visningsnamn | F6: Typ | G6: Nuvarande webbpris | H6: Nuvarande timmar | I6: Offert? | J6: Använd intern kalkyl? | K6: Internt kalkylpris | L6: Interna timmar | M6: Exportpris | N6: Exporttimmar | O6: Notering | Q6: Paket-ID | R6: Del-ID | S6: Benämning | T6: Antal | U6: Enhet | V6: Inköpspris/st | W6: Material | X6: Arbete h/st | Y6: Timmar | Z6: Timpris | AA6: Arbete | AB6: Övrigt | AC6: Påslag % | AD6: Budgetpris | AE6: Kommentar
A7: Ja | B7: hallType | C7: simple | D7: hallType:simple | E7: Halltyp och grundlogik | F7: Fast | G7: 0 | H7: 0 | I7: Nej | J7: Nej | K7: =IF(D7="","",SUMIF($Q$7:$Q$126,D7,$AD$7:$AD$126)) -> 0 | L7: =IF(D7="","",SUMIF($Q$7:$Q$126,D7,$Y$7:$Y$126)) -> 0 | M7: =IF(D7="","",IF(J7="Ja",K7,G7)) -> 0 | N7: =IF(D7="","",IF(J7="Ja",L7,H7)) -> 0 | O7: Enkel sporthall vald. | Q7: hallType:dividable | R7: START-dividable | S7: Startmaterial / ersätt med verklig delkalkyl | T7: 1 | U7: paket | V7: 18339.13 | W7: =IF(OR(T7="",V7=""),0,T7*V7) -> 18339.13 | X7: 4 | Y7: =IF(OR(T7="",X7=""),0,T7*X7) -> 4 | Z7: =IF(Inställningar!$B$5="",0,Inställningar!$B$5) -> 850 | AA7: =Y7*Z7 -> 3400 | AB7: 0 | AC7: =IF(Inställningar!$B$6="",0,Inställningar!$B$6) -> 0.15 | AD7: =ROUND((W7+AA7+IF(AB7="",0,AB7))*(1+AC7),0) -> 25000 | AE7: Källa: HTML-startvärde. Generisk startfördelning för test; byt mot verkliga komponenter.
A8: Ja | B8: hallType | C8: dividable | D8: hallType:dividable | E8: Halltyp och grundlogik | F8: Fast | G8: 25000 | H8: 4 | I8: Nej | J8: Ja | K8: =IF(D8="","",SUMIF($Q$7:$Q$126,D8,$AD$7:$AD$126)) -> 25000 | L8: =IF(D8="","",SUMIF($Q$7:$Q$126,D8,$Y$7:$Y$126)) -> 4 | M8: =IF(D8="","",IF(J8="Ja",K8,G8)) -> 25000 | N8: =IF(D8="","",IF(J8="Ja",L8,H8)) -> 4 | O8: Delbar hall med A/B-logik. | Q8: hallType:stands | R8: START-stands | S8: Startmaterial / ersätt med verklig delkalkyl | T8: 1 | U8: paket | V8: 11402.174 | W8: =IF(OR(T8="",V8=""),0,T8*V8) -> 11402.174 | X8: 5 | Y8: =IF(OR(T8="",X8=""),0,T8*X8) -> 5 | Z8: =IF(Inställningar!$B$5="",0,Inställningar!$B$5) -> 850 | AA8: =Y8*Z8 -> 4250 | AB8: 0 | AC8: =IF(Inställningar!$B$6="",0,Inställningar!$B$6) -> 0.15 | AD8: =ROUND((W8+AA8+IF(AB8="",0,AB8))*(1+AC8),0) -> 18000 | AE8: Källa: HTML-startvärde. Generisk startfördelning för test; byt mot verkliga komponenter.
A9: Ja | B9: hallType | C9: stands | D9: hallType:stands | E9: Halltyp och grundlogik | F9: Fast | G9: 18000 | H9: 5 | I9: Nej | J9: Ja | K9: =IF(D9="","",SUMIF($Q$7:$Q$126,D9,$AD$7:$AD$126)) -> 18000 | L9: =IF(D9="","",SUMIF($Q$7:$Q$126,D9,$Y$7:$Y$126)) -> 5 | M9: =IF(D9="","",IF(J9="Ja",K9,G9)) -> 18000 | N9: =IF(D9="","",IF(J9="Ja",L9,H9)) -> 5 | O9: Hall med läktare och publiklogik. | Q9: hallType:sti | R9: START-sti | S9: Startmaterial / ersätt med verklig delkalkyl | T9: 1 | U9: paket | V9: 19286.957 | W9: =IF(OR(T9="",V9=""),0,T9*V9) -> 19286.957 | X9: 8 | Y9: =IF(OR(T9="",X9=""),0,T9*X9) -> 8 | Z9: =IF(Inställningar!$B$5="",0,Inställningar!$B$5) -> 850 | AA9: =Y9*Z9 -> 6800 | AB9: 0 | AC9: =IF(Inställningar!$B$6="",0,Inställningar!$B$6) -> 0.15 | AD9: =ROUND((W9+AA9+IF(AB9="",0,AB9))*(1+AC9),0) -> 30000 | AE9: Källa: HTML-startvärde. Generisk startfördelning för test; byt mot verkliga komponenter.
A10: Ja | B10: hallType | C10: sti | D10: hallType:sti | E10: Halltyp och grundlogik | F10: Fast | G10: 30000 | H10: 8 | I10: Nej | J10: Ja | K10: =IF(D10="","",SUMIF($Q$7:$Q$126,D10,$AD$7:$AD$126)) -> 30000 | L10: =IF(D10="","",SUMIF($Q$7:$Q$126,D10,$Y$7:$Y$126)) -> 8 | M10: =IF(D10="","",IF(J10="Ja",K10,G10)) -> 30000 | N10: =IF(D10="","",IF(J10="Ja",L10,H10)) -> 8 | O10: Hall med fördjupad taluppfattbarhet. | Q10: basePackage:simple | R10: START-simple | S10: Startmaterial / ersätt med verklig delkalkyl | T10: 1 | U10: paket | V10: 69917.391 | W10: =IF(OR(T10="",V10=""),0,T10*V10) -> 69917.391 | X10: 18 | Y10: =IF(OR(T10="",X10=""),0,T10*X10) -> 18 | Z10: =IF(Inställningar!$B$5="",0,Inställningar!$B$5) -> 850 | AA10: =Y10*Z10 -> 15300 | AB10: 0 | AC10: =IF(Inställningar!$B$6="",0,Inställningar!$B$6) -> 0.15 | AD10: =ROUND((W10+AA10+IF(AB10="",0,AB10))*(1+AC10),0) -> 98000 | AE10: Källa: HTML-startvärde. Generisk startfördelning för test; byt mot verkliga komponenter.
A11: Ja | B11: basePackage | C11: simple | D11: basePackage:simple | E11: Basljud sporthall | F11: Fast | G11: 98000 | H11: 18 | I11: Nej | J11: Ja | K11: =IF(D11="","",SUMIF($Q$7:$Q$126,D11,$AD$7:$AD$126)) -> 98000 | L11: =IF(D11="","",SUMIF($Q$7:$Q$126,D11,$Y$7:$Y$126)) -> 18 | M11: =IF(D11="","",IF(J11="Ja",K11,G11)) -> 98000 | N11: =IF(D11="","",IF(J11="Ja",L11,H11)) -> 18 | O11: Budgetpost för huvudljud och grundläggande drift. | Q11: basePackage:dsp | R11: START-dsp | S11: Startmaterial / ersätt med verklig delkalkyl | T11: 1 | U11: paket | V11: 88256.522 | W11: =IF(OR(T11="",V11=""),0,T11*V11) -> 88256.522 | X11: 22 | Y11: =IF(OR(T11="",X11=""),0,T11*X11) -> 22 | Z11: =IF(Inställningar!$B$5="",0,Inställningar!$B$5) -> 850 | AA11: =Y11*Z11 -> 18700 | AB11: 0 | AC11: =IF(Inställningar!$B$6="",0,Inställningar!$B$6) -> 0.15 | AD11: =ROUND((W11+AA11+IF(AB11="",0,AB11))*(1+AC11),0) -> 123000 | AE11: Källa: HTML-startvärde. Generisk startfördelning för test; byt mot verkliga komponenter.
A12: Ja | B12: basePackage | C12: dsp | D12: basePackage:dsp | E12: Basljud sporthall | F12: Fast | G12: 123000 | H12: 22 | I12: Nej | J12: Ja | K12: =IF(D12="","",SUMIF($Q$7:$Q$126,D12,$AD$7:$AD$126)) -> 123000 | L12: =IF(D12="","",SUMIF($Q$7:$Q$126,D12,$Y$7:$Y$126)) -> 22 | M12: =IF(D12="","",IF(J12="Ja",K12,G12)) -> 123000 | N12: =IF(D12="","",IF(J12="Ja",L12,H12)) -> 22 | O12: Budgetpost för huvudljud med DSP och zonlogik. | Q12: standsSound:eight12 | R12: START-eight12 | S12: Startmaterial / ersätt med verklig delkalkyl | T12: 1 | U12: paket | V12: 41973.913 | W12: =IF(OR(T12="",V12=""),0,T12*V12) -> 41973.913 | X12: 12 | Y12: =IF(OR(T12="",X12=""),0,T12*X12) -> 12 | Z12: =IF(Inställningar!$B$5="",0,Inställningar!$B$5) -> 850 | AA12: =Y12*Z12 -> 10200 | AB12: 0 | AC12: =IF(Inställningar!$B$6="",0,Inställningar!$B$6) -> 0.15 | AD12: =ROUND((W12+AA12+IF(AB12="",0,AB12))*(1+AC12),0) -> 60000 | AE12: Källa: HTML-startvärde. Generisk startfördelning för test; byt mot verkliga komponenter.
A13: Ja | B13: standsSound | C13: none | D13: standsSound:none | E13: Läktarljud | F13: Fast | G13: 0 | H13: 0 | I13: Nej | J13: Nej | K13: =IF(D13="","",SUMIF($Q$7:$Q$126,D13,$AD$7:$AD$126)) -> 0 | L13: =IF(D13="","",SUMIF($Q$7:$Q$126,D13,$Y$7:$Y$126)) -> 0 | M13: =IF(D13="","",IF(J13="Ja",K13,G13)) -> 0 | N13: =IF(D13="","",IF(J13="Ja",L13,H13)) -> 0 | Q13: control:knob | R13: START-knob | S13: Startmaterial / ersätt med verklig delkalkyl | T13: 1 | U13: paket | V13: 3952.1739 | W13: =IF(OR(T13="",V13=""),0,T13*V13) -> 3952.1739 | X13: 2 | Y13: =IF(OR(T13="",X13=""),0,T13*X13) -> 2 | Z13: =IF(Inställningar!$B$5="",0,Inställningar!$B$5) -> 850 | AA13: =Y13*Z13 -> 1700 | AB13: 0 | AC13: =IF(Inställningar!$B$6="",0,Inställningar!$B$6) -> 0.15 | AD13: =ROUND((W13+AA13+IF(AB13="",0,AB13))*(1+AC13),0) -> 6500 | AE13: Källa: HTML-startvärde. Generisk startfördelning för test; byt mot verkliga komponenter.
A14: Ja | B14: standsSound | C14: eight12 | D14: standsSound:eight12 | E14: Läktarljud för sporthall | F14: Fast | G14: 60000 | H14: 12 | I14: Nej | J14: Ja | K14: =IF(D14="","",SUMIF($Q$7:$Q$126,D14,$AD$7:$AD$126)) -> 60000 | L14: =IF(D14="","",SUMIF($Q$7:$Q$126,D14,$Y$7:$Y$126)) -> 12 | M14: =IF(D14="","",IF(J14="Ja",K14,G14)) -> 60000 | N14: =IF(D14="","",IF(J14="Ja",L14,H14)) -> 12 | O14: Budgetpost för separat ljud mot läktare. | Q14: control:touch | R14: START-touch | S14: Startmaterial / ersätt med verklig delkalkyl | T14: 1 | U14: paket | V14: 20967.391 | W14: =IF(OR(T14="",V14=""),0,T14*V14) -> 20967.391 | X14: 5 | Y14: =IF(OR(T14="",X14=""),0,T14*X14) -> 5 | Z14: =IF(Inställningar!$B$5="",0,Inställningar!$B$5) -> 850 | AA14: =Y14*Z14 -> 4250 | AB14: 0 | AC14: =IF(Inställningar!$B$6="",0,Inställningar!$B$6) -> 0.15 | AD14: =ROUND((W14+AA14+IF(AB14="",0,AB14))*(1+AC14),0) -> 29000 | AE14: Källa: HTML-startvärde. Generisk startfördelning för test; byt mot verkliga komponenter.
A15: Ja | B15: control | C15: knob | D15: control:knob | E15: Styrning | F15: Fast | G15: 6500 | H15: 2 | I15: Nej | J15: Ja | K15: =IF(D15="","",SUMIF($Q$7:$Q$126,D15,$AD$7:$AD$126)) -> 6500 | L15: =IF(D15="","",SUMIF($Q$7:$Q$126,D15,$Y$7:$Y$126)) -> 2 | M15: =IF(D15="","",IF(J15="Ja",K15,G15)) -> 6500 | N15: =IF(D15="","",IF(J15="Ja",L15,H15)) -> 2 | O15: Vridreglage och enkel användning. | Q15: loopPlan:standard | R15: START-standard | S15: Startmaterial / ersätt med verklig delkalkyl | T15: 1 | U15: paket | V15: 98095.652 | W15: =IF(OR(T15="",V15=""),0,T15*V15) -> 98095.652 | X15: 36 | Y15: =IF(OR(T15="",X15=""),0,T15*X15) -> 36 | Z15: =IF(Inställningar!$B$5="",0,Inställningar!$B$5) -> 850 | AA15: =Y15*Z15 -> 30600 | AB15: 0 | AC15: =IF(Inställningar!$B$6="",0,Inställningar!$B$6) -> 0.15 | AD15: =ROUND((W15+AA15+IF(AB15="",0,AB15))*(1+AC15),0) -> 148000 | AE15: Källa: HTML-startvärde. Generisk startfördelning för test; byt mot verkliga komponenter.
A16: Ja | B16: control | C16: touch | D16: control:touch | E16: Styrning | F16: Fast | G16: 29000 | H16: 5 | I16: Nej | J16: Ja | K16: =IF(D16="","",SUMIF($Q$7:$Q$126,D16,$AD$7:$AD$126)) -> 29000 | L16: =IF(D16="","",SUMIF($Q$7:$Q$126,D16,$Y$7:$Y$126)) -> 5 | M16: =IF(D16="","",IF(J16="Ja",K16,G16)) -> 29000 | N16: =IF(D16="","",IF(J16="Ja",L16,H16)) -> 5 | O16: Touchpanel och tydliga användarlägen. | Q16: auracast:basic | R16: START-basic | S16: Startmaterial / ersätt med verklig delkalkyl | T16: 1 | U16: paket | V16: 27054.348 | W16: =IF(OR(T16="",V16=""),0,T16*V16) -> 27054.348 | X16: 5 | Y16: =IF(OR(T16="",X16=""),0,T16*X16) -> 5 | Z16: =IF(Inställningar!$B$5="",0,Inställningar!$B$5) -> 850 | AA16: =Y16*Z16 -> 4250 | AB16: 0 | AC16: =IF(Inställningar!$B$6="",0,Inställningar!$B$6) -> 0.15 | AD16: =ROUND((W16+AA16+IF(AB16="",0,AB16))*(1+AC16),0) -> 36000 | AE16: Källa: HTML-startvärde. Generisk startfördelning för test; byt mot verkliga komponenter.
A17: Ja | B17: loopPlan | C17: none | D17: loopPlan:none | E17: Hörslinga, Auracast och tillgänglighet | F17: Fast | G17: 0 | H17: 0 | I17: Nej | J17: Nej | K17: =IF(D17="","",SUMIF($Q$7:$Q$126,D17,$AD$7:$AD$126)) -> 0 | L17: =IF(D17="","",SUMIF($Q$7:$Q$126,D17,$Y$7:$Y$126)) -> 0 | M17: =IF(D17="","",IF(J17="Ja",K17,G17)) -> 0 | N17: =IF(D17="","",IF(J17="Ja",L17,H17)) -> 0 | Q17: sti:050 | R17: START-050 | S17: Startmaterial / ersätt med verklig delkalkyl | T17: 1 | U17: paket | V17: 14069.565 | W17: =IF(OR(T17="",V17=""),0,T17*V17) -> 14069.565 | X17: 8 | Y17: =IF(OR(T17="",X17=""),0,T17*X17) -> 8 | Z17: =IF(Inställningar!$B$5="",0,Inställningar!$B$5) -> 850 | AA17: =Y17*Z17 -> 6800 | AB17: 0 | AC17: =IF(Inställningar!$B$6="",0,Inställningar!$B$6) -> 0.15 | AD17: =ROUND((W17+AA17+IF(AB17="",0,AB17))*(1+AC17),0) -> 24000 | AE17: Källa: HTML-startvärde. Generisk startfördelning för test; byt mot verkliga komponenter.
A18: Ja | B18: loopPlan | C18: standard | D18: loopPlan:standard | E18: Hörslinga, Auracast och tillgänglighet | F18: Fast | G18: 148000 | H18: 36 | I18: Nej | J18: Ja | K18: =IF(D18="","",SUMIF($Q$7:$Q$126,D18,$AD$7:$AD$126)) -> 148000 | L18: =IF(D18="","",SUMIF($Q$7:$Q$126,D18,$Y$7:$Y$126)) -> 36 | M18: =IF(D18="","",IF(J18="Ja",K18,G18)) -> 148000 | N18: =IF(D18="","",IF(J18="Ja",L18,H18)) -> 36 | O18: Budgetpost för standardplan. | Q18: sti:060 | R18: START-060 | S18: Startmaterial / ersätt med verklig delkalkyl | T18: 1 | U18: paket | V18: 23713.043 | W18: =IF(OR(T18="",V18=""),0,T18*V18) -> 23713.043 | X18: 12 | Y18: =IF(OR(T18="",X18=""),0,T18*X18) -> 12 | Z18: =IF(Inställningar!$B$5="",0,Inställningar!$B$5) -> 850 | AA18: =Y18*Z18 -> 10200 | AB18: 0 | AC18: =IF(Inställningar!$B$6="",0,Inställningar!$B$6) -> 0.15 | AD18: =ROUND((W18+AA18+IF(AB18="",0,AB18))*(1+AC18),0) -> 39000 | AE18: Källa: HTML-startvärde. Generisk startfördelning för test; byt mot verkliga komponenter.
A19: Ja | B19: loopPlan | C19: custom | D19: loopPlan:custom | E19: Hörslinga, Auracast och tillgänglighet | F19: Offert | G19: 0 | H19: 0 | I19: Ja | J19: Nej | K19: =IF(D19="","",SUMIF($Q$7:$Q$126,D19,$AD$7:$AD$126)) -> 0 | L19: =IF(D19="","",SUMIF($Q$7:$Q$126,D19,$Y$7:$Y$126)) -> 0 | M19: =IF(D19="","",IF(J19="Ja",K19,G19)) -> 0 | N19: =IF(D19="","",IF(J19="Ja",L19,H19)) -> 0 | O19: Annan planstorlek kräver separat offert. | Q19: unit:handMic | R19: START-handMic | S19: Startmaterial / ersätt med verklig delkalkyl | T19: 1 | U19: paket | V19: 6444.5652 | W19: =IF(OR(T19="",V19=""),0,T19*V19) -> 6444.5652 | X19: 0.5 | Y19: =IF(OR(T19="",X19=""),0,T19*X19) -> 0.5 | Z19: =IF(Inställningar!$B$5="",0,Inställningar!$B$5) -> 850 | AA19: =Y19*Z19 -> 425 | AB19: 0 | AC19: =IF(Inställningar!$B$6="",0,Inställningar!$B$6) -> 0.15 | AD19: =ROUND((W19+AA19+IF(AB19="",0,AB19))*(1+AC19),0) -> 7900 | AE19: Källa: HTML-startvärde. Generisk startfördelning för test; byt mot verkliga komponenter.
A20: Ja | B20: auracast | C20: none | D20: auracast:none | E20: Hörslinga, Auracast och tillgänglighet | F20: Fast | G20: 0 | H20: 0 | I20: Nej | J20: Nej | K20: =IF(D20="","",SUMIF($Q$7:$Q$126,D20,$AD$7:$AD$126)) -> 0 | L20: =IF(D20="","",SUMIF($Q$7:$Q$126,D20,$Y$7:$Y$126)) -> 0 | M20: =IF(D20="","",IF(J20="Ja",K20,G20)) -> 0 | N20: =IF(D20="","",IF(J20="Ja",L20,H20)) -> 0 | Q20: unit:headset | R20: START-headset | S20: Startmaterial / ersätt med verklig delkalkyl | T20: 1 | U20: paket | V20: 7575 | W20: =IF(OR(T20="",V20=""),0,T20*V20) -> 7575 | X20: 0.5 | Y20: =IF(OR(T20="",X20=""),0,T20*X20) -> 0.5 | Z20: =IF(Inställningar!$B$5="",0,Inställningar!$B$5) -> 850 | AA20: =Y20*Z20 -> 425 | AB20: 0 | AC20: =IF(Inställningar!$B$6="",0,Inställningar!$B$6) -> 0.15 | AD20: =ROUND((W20+AA20+IF(AB20="",0,AB20))*(1+AC20),0) -> 9200 | AE20: Källa: HTML-startvärde. Generisk startfördelning för test; byt mot verkliga komponenter.
A21: Ja | B21: auracast | C21: basic | D21: auracast:basic | E21: Hörslinga, Auracast och tillgänglighet | F21: Fast | G21: 36000 | H21: 5 | I21: Nej | J21: Ja | K21: =IF(D21="","",SUMIF($Q$7:$Q$126,D21,$AD$7:$AD$126)) -> 36000 | L21: =IF(D21="","",SUMIF($Q$7:$Q$126,D21,$Y$7:$Y$126)) -> 5 | M21: =IF(D21="","",IF(J21="Ja",K21,G21)) -> 36000 | N21: =IF(D21="","",IF(J21="Ja",L21,H21)) -> 5 | O21: Auracast som komplement. | Q21: unit:bluetooth | R21: START-bluetooth | S21: Startmaterial / ersätt med verklig delkalkyl | T21: 1 | U21: paket | V21: 3227.1739 | W21: =IF(OR(T21="",V21=""),0,T21*V21) -> 3227.1739 | X21: 0.5 | Y21: =IF(OR(T21="",X21=""),0,T21*X21) -> 0.5 | Z21: =IF(Inställningar!$B$5="",0,Inställningar!$B$5) -> 850 | AA21: =Y21*Z21 -> 425 | AB21: 0 | AC21: =IF(Inställningar!$B$6="",0,Inställningar!$B$6) -> 0.15 | AD21: =ROUND((W21+AA21+IF(AB21="",0,AB21))*(1+AC21),0) -> 4200 | AE21: Källa: HTML-startvärde. Generisk startfördelning för test; byt mot verkliga komponenter.
A22: Ja | B22: sti | C22: none | D22: sti:none | E22: STI och inmätning | F22: Fast | G22: 0 | H22: 0 | I22: Nej | J22: Nej | K22: =IF(D22="","",SUMIF($Q$7:$Q$126,D22,$AD$7:$AD$126)) -> 0 | L22: =IF(D22="","",SUMIF($Q$7:$Q$126,D22,$Y$7:$Y$126)) -> 0 | M22: =IF(D22="","",IF(J22="Ja",K22,G22)) -> 0 | N22: =IF(D22="","",IF(J22="Ja",L22,H22)) -> 0 | Q22: unit:zoneSmall | R22: START-zoneSmall | S22: Startmaterial / ersätt med verklig delkalkyl | T22: 1 | U22: paket | V22: 10986.957 | W22: =IF(OR(T22="",V22=""),0,T22*V22) -> 10986.957 | X22: 6 | Y22: =IF(OR(T22="",X22=""),0,T22*X22) -> 6 | Z22: =IF(Inställningar!$B$5="",0,Inställningar!$B$5) -> 850 | AA22: =Y22*Z22 -> 5100 | AB22: 0 | AC22: =IF(Inställningar!$B$6="",0,Inställningar!$B$6) -> 0.15 | AD22: =ROUND((W22+AA22+IF(AB22="",0,AB22))*(1+AC22),0) -> 18500 | AE22: Källa: HTML-startvärde. Generisk startfördelning för test; byt mot verkliga komponenter.
A23: Ja | B23: sti | C23: 050 | D23: sti:050 | E23: STI och inmätning | F23: Fast | G23: 24000 | H23: 8 | I23: Nej | J23: Ja | K23: =IF(D23="","",SUMIF($Q$7:$Q$126,D23,$AD$7:$AD$126)) -> 24000 | L23: =IF(D23="","",SUMIF($Q$7:$Q$126,D23,$Y$7:$Y$126)) -> 8 | M23: =IF(D23="","",IF(J23="Ja",K23,G23)) -> 24000 | N23: =IF(D23="","",IF(J23="Ja",L23,H23)) -> 8 | O23: Budgetpost för STI 0,50. | Q23: unit:zoneMedium | R23: START-zoneMedium | S23: Startmaterial / ersätt med verklig delkalkyl | T23: 1 | U23: paket | V23: 18852.174 | W23: =IF(OR(T23="",V23=""),0,T23*V23) -> 18852.174 | X23: 8 | Y23: =IF(OR(T23="",X23=""),0,T23*X23) -> 8 | Z23: =IF(Inställningar!$B$5="",0,Inställningar!$B$5) -> 850 | AA23: =Y23*Z23 -> 6800 | AB23: 0 | AC23: =IF(Inställningar!$B$6="",0,Inställningar!$B$6) -> 0.15 | AD23: =ROUND((W23+AA23+IF(AB23="",0,AB23))*(1+AC23),0) -> 29500 | AE23: Källa: HTML-startvärde. Generisk startfördelning för test; byt mot verkliga komponenter.
A24: Ja | B24: sti | C24: 060 | D24: sti:060 | E24: STI och inmätning | F24: Fast | G24: 39000 | H24: 12 | I24: Nej | J24: Ja | K24: =IF(D24="","",SUMIF($Q$7:$Q$126,D24,$AD$7:$AD$126)) -> 39000 | L24: =IF(D24="","",SUMIF($Q$7:$Q$126,D24,$Y$7:$Y$126)) -> 12 | M24: =IF(D24="","",IF(J24="Ja",K24,G24)) -> 39000 | N24: =IF(D24="","",IF(J24="Ja",L24,H24)) -> 12 | O24: Budgetpost för STI 0,60. | Q24: unit:zoneLarge | R24: START-zoneLarge | S24: Startmaterial / ersätt med verklig delkalkyl | T24: 1 | U24: paket | V24: 29800 | W24: =IF(OR(T24="",V24=""),0,T24*V24) -> 29800 | X24: 12 | Y24: =IF(OR(T24="",X24=""),0,T24*X24) -> 12 | Z24: =IF(Inställningar!$B$5="",0,Inställningar!$B$5) -> 850 | AA24: =Y24*Z24 -> 10200 | AB24: 0 | AC24: =IF(Inställningar!$B$6="",0,Inställningar!$B$6) -> 0.15 | AD24: =ROUND((W24+AA24+IF(AB24="",0,AB24))*(1+AC24),0) -> 46000 | AE24: Källa: HTML-startvärde. Generisk startfördelning för test; byt mot verkliga komponenter.
A25: Ja | B25: sti | C25: 070 | D25: sti:070 | E25: STI och inmätning | F25: Offert | G25: 0 | H25: 0 | I25: Ja | J25: Nej | K25: =IF(D25="","",SUMIF($Q$7:$Q$126,D25,$AD$7:$AD$126)) -> 0 | L25: =IF(D25="","",SUMIF($Q$7:$Q$126,D25,$Y$7:$Y$126)) -> 0 | M25: =IF(D25="","",IF(J25="Ja",K25,G25)) -> 0 | N25: =IF(D25="","",IF(J25="Ja",L25,H25)) -> 0 | O25: Högre STI-krav behöver separat projektering. | Q25: stands:small | R25: START-small | S25: Startmaterial / ersätt med verklig delkalkyl | T25: 1 | U25: paket | V25: 22765.217 | W25: =IF(OR(T25="",V25=""),0,T25*V25) -> 22765.217 | X25: 8 | Y25: =IF(OR(T25="",X25=""),0,T25*X25) -> 8 | Z25: =IF(Inställningar!$B$5="",0,Inställningar!$B$5) -> 850 | AA25: =Y25*Z25 -> 6800 | AB25: 0 | AC25: =IF(Inställningar!$B$6="",0,Inställningar!$B$6) -> 0.15 | AD25: =ROUND((W25+AA25+IF(AB25="",0,AB25))*(1+AC25),0) -> 34000 | AE25: Källa: HTML-startvärde. Generisk startfördelning för test; byt mot verkliga komponenter.
A26: Ja | B26: unit | C26: handMic | D26: unit:handMic | E26: Mikrofoner och anslutning | F26: Enhet | G26: 7900 | H26: 0.5 | I26: Nej | J26: Ja | K26: =IF(D26="","",SUMIF($Q$7:$Q$126,D26,$AD$7:$AD$126)) -> 7900 | L26: =IF(D26="","",SUMIF($Q$7:$Q$126,D26,$Y$7:$Y$126)) -> 0.5 | M26: =IF(D26="","",IF(J26="Ja",K26,G26)) -> 7900 | N26: =IF(D26="","",IF(J26="Ja",L26,H26)) -> 0.5 | O26: Pris per trådlös handmikrofon. | Q26: stands:medium | R26: START-medium | S26: Startmaterial / ersätt med verklig delkalkyl | T26: 1 | U26: paket | V26: 35017.391 | W26: =IF(OR(T26="",V26=""),0,T26*V26) -> 35017.391 | X26: 12 | Y26: =IF(OR(T26="",X26=""),0,T26*X26) -> 12 | Z26: =IF(Inställningar!$B$5="",0,Inställningar!$B$5) -> 850 | AA26: =Y26*Z26 -> 10200 | AB26: 0 | AC26: =IF(Inställningar!$B$6="",0,Inställningar!$B$6) -> 0.15 | AD26: =ROUND((W26+AA26+IF(AB26="",0,AB26))*(1+AC26),0) -> 52000 | AE26: Källa: HTML-startvärde. Generisk startfördelning för test; byt mot verkliga komponenter.
A27: Ja | B27: unit | C27: headset | D27: unit:headset | E27: Mikrofoner och anslutning | F27: Enhet | G27: 9200 | H27: 0.5 | I27: Nej | J27: Ja | K27: =IF(D27="","",SUMIF($Q$7:$Q$126,D27,$AD$7:$AD$126)) -> 9200 | L27: =IF(D27="","",SUMIF($Q$7:$Q$126,D27,$Y$7:$Y$126)) -> 0.5 | M27: =IF(D27="","",IF(J27="Ja",K27,G27)) -> 9200 | N27: =IF(D27="","",IF(J27="Ja",L27,H27)) -> 0.5 | O27: Pris per trådlöst headset. | Q27: stands:large | R27: START-large | S27: Startmaterial / ersätt med verklig delkalkyl | T27: 1 | U27: paket | V27: 53395.652 | W27: =IF(OR(T27="",V27=""),0,T27*V27) -> 53395.652 | X27: 18 | Y27: =IF(OR(T27="",X27=""),0,T27*X27) -> 18 | Z27: =IF(Inställningar!$B$5="",0,Inställningar!$B$5) -> 850 | AA27: =Y27*Z27 -> 15300 | AB27: 0 | AC27: =IF(Inställningar!$B$6="",0,Inställningar!$B$6) -> 0.15 | AD27: =ROUND((W27+AA27+IF(AB27="",0,AB27))*(1+AC27),0) -> 79000 | AE27: Källa: HTML-startvärde. Generisk startfördelning för test; byt mot verkliga komponenter.
A28: Ja | B28: unit | C28: bluetooth | D28: unit:bluetooth | E28: Mikrofoner och anslutning | F28: Enhet | G28: 4200 | H28: 0.5 | I28: Nej | J28: Ja | K28: =IF(D28="","",SUMIF($Q$7:$Q$126,D28,$AD$7:$AD$126)) -> 4200 | L28: =IF(D28="","",SUMIF($Q$7:$Q$126,D28,$Y$7:$Y$126)) -> 0.5 | M28: =IF(D28="","",IF(J28="Ja",K28,G28)) -> 4200 | N28: =IF(D28="","",IF(J28="Ja",L28,H28)) -> 0.5 | O28: Pris per Bluetooth-mottagare. | Q28: checks:documentation | R28: START-documentation | S28: Startmaterial / ersätt med verklig delkalkyl | T28: 1 | U28: paket | V28: 7034.7826 | W28: =IF(OR(T28="",V28=""),0,T28*V28) -> 7034.7826 | X28: 4 | Y28: =IF(OR(T28="",X28=""),0,T28*X28) -> 4 | Z28: =IF(Inställningar!$B$5="",0,Inställningar!$B$5) -> 850 | AA28: =Y28*Z28 -> 3400 | AB28: 0 | AC28: =IF(Inställningar!$B$6="",0,Inställningar!$B$6) -> 0.15 | AD28: =ROUND((W28+AA28+IF(AB28="",0,AB28))*(1+AC28),0) -> 12000 | AE28: Källa: HTML-startvärde. Generisk startfördelning för test; byt mot verkliga komponenter.
A29: Ja | B29: unit | C29: zoneSmall | D29: unit:zoneSmall | E29: Extra ljudzoner | F29: Enhet | G29: 18500 | H29: 6 | I29: Nej | J29: Ja | K29: =IF(D29="","",SUMIF($Q$7:$Q$126,D29,$AD$7:$AD$126)) -> 18500 | L29: =IF(D29="","",SUMIF($Q$7:$Q$126,D29,$Y$7:$Y$126)) -> 6 | M29: =IF(D29="","",IF(J29="Ja",K29,G29)) -> 18500 | N29: =IF(D29="","",IF(J29="Ja",L29,H29)) -> 6 | O29: Zon 20–50 m². | W29: =IF(OR(T29="",V29=""),0,T29*V29) -> 0 | Y29: =IF(OR(T29="",X29=""),0,T29*X29) -> 0 | Z29: =IF(Inställningar!$B$5="",0,Inställningar!$B$5) -> 850 | AA29: =Y29*Z29 -> 0 | AC29: =IF(Inställningar!$B$6="",0,Inställningar!$B$6) -> 0.15 | AD29: =ROUND((W29+AA29+IF(AB29="",0,AB29))*(1+AC29),0) -> 0
A30: Ja | B30: unit | C30: zoneMedium | D30: unit:zoneMedium | E30: Extra ljudzoner | F30: Enhet | G30: 29500 | H30: 8 | I30: Nej | J30: Ja | K30: =IF(D30="","",SUMIF($Q$7:$Q$126,D30,$AD$7:$AD$126)) -> 29500 | L30: =IF(D30="","",SUMIF($Q$7:$Q$126,D30,$Y$7:$Y$126)) -> 8 | M30: =IF(D30="","",IF(J30="Ja",K30,G30)) -> 29500 | N30: =IF(D30="","",IF(J30="Ja",L30,H30)) -> 8 | O30: Zon 50–100 m². | W30: =IF(OR(T30="",V30=""),0,T30*V30) -> 0 | Y30: =IF(OR(T30="",X30=""),0,T30*X30) -> 0 | Z30: =IF(Inställningar!$B$5="",0,Inställningar!$B$5) -> 850 | AA30: =Y30*Z30 -> 0 | AC30: =IF(Inställningar!$B$6="",0,Inställningar!$B$6) -> 0.15 | AD30: =ROUND((W30+AA30+IF(AB30="",0,AB30))*(1+AC30),0) -> 0
A31: Ja | B31: unit | C31: zoneLarge | D31: unit:zoneLarge | E31: Extra ljudzoner | F31: Enhet | G31: 46000 | H31: 12 | I31: Nej | J31: Ja | K31: =IF(D31="","",SUMIF($Q$7:$Q$126,D31,$AD$7:$AD$126)) -> 46000 | L31: =IF(D31="","",SUMIF($Q$7:$Q$126,D31,$Y$7:$Y$126)) -> 12 | M31: =IF(D31="","",IF(J31="Ja",K31,G31)) -> 46000 | N31: =IF(D31="","",IF(J31="Ja",L31,H31)) -> 12 | O31: Zon 100–200 m². | W31: =IF(OR(T31="",V31=""),0,T31*V31) -> 0 | Y31: =IF(OR(T31="",X31=""),0,T31*X31) -> 0 | Z31: =IF(Inställningar!$B$5="",0,Inställningar!$B$5) -> 850 | AA31: =Y31*Z31 -> 0 | AC31: =IF(Inställningar!$B$6="",0,Inställningar!$B$6) -> 0.15 | AD31: =ROUND((W31+AA31+IF(AB31="",0,AB31))*(1+AC31),0) -> 0
A32: Ja | B32: stands | C32: small | D32: stands:small | E32: Läktare grundpaket | F32: Fast | G32: 34000 | H32: 8 | I32: Nej | J32: Ja | K32: =IF(D32="","",SUMIF($Q$7:$Q$126,D32,$AD$7:$AD$126)) -> 34000 | L32: =IF(D32="","",SUMIF($Q$7:$Q$126,D32,$Y$7:$Y$126)) -> 8 | M32: =IF(D32="","",IF(J32="Ja",K32,G32)) -> 34000 | N32: =IF(D32="","",IF(J32="Ja",L32,H32)) -> 8 | O32: Läktare 8–20 m², före tillgänglighetsmultiplikator. | W32: =IF(OR(T32="",V32=""),0,T32*V32) -> 0 | Y32: =IF(OR(T32="",X32=""),0,T32*X32) -> 0 | Z32: =IF(Inställningar!$B$5="",0,Inställningar!$B$5) -> 850 | AA32: =Y32*Z32 -> 0 | AC32: =IF(Inställningar!$B$6="",0,Inställningar!$B$6) -> 0.15 | AD32: =ROUND((W32+AA32+IF(AB32="",0,AB32))*(1+AC32),0) -> 0
A33: Ja | B33: stands | C33: medium | D33: stands:medium | E33: Läktare grundpaket | F33: Fast | G33: 52000 | H33: 12 | I33: Nej | J33: Ja | K33: =IF(D33="","",SUMIF($Q$7:$Q$126,D33,$AD$7:$AD$126)) -> 52000 | L33: =IF(D33="","",SUMIF($Q$7:$Q$126,D33,$Y$7:$Y$126)) -> 12 | M33: =IF(D33="","",IF(J33="Ja",K33,G33)) -> 52000 | N33: =IF(D33="","",IF(J33="Ja",L33,H33)) -> 12 | O33: Läktare 20–40 m², före tillgänglighetsmultiplikator. | W33: =IF(OR(T33="",V33=""),0,T33*V33) -> 0 | Y33: =IF(OR(T33="",X33=""),0,T33*X33) -> 0 | Z33: =IF(Inställningar!$B$5="",0,Inställningar!$B$5) -> 850 | AA33: =Y33*Z33 -> 0 | AC33: =IF(Inställningar!$B$6="",0,Inställningar!$B$6) -> 0.15 | AD33: =ROUND((W33+AA33+IF(AB33="",0,AB33))*(1+AC33),0) -> 0
A34: Ja | B34: stands | C34: large | D34: stands:large | E34: Läktare grundpaket | F34: Fast | G34: 79000 | H34: 18 | I34: Nej | J34: Ja | K34: =IF(D34="","",SUMIF($Q$7:$Q$126,D34,$AD$7:$AD$126)) -> 79000 | L34: =IF(D34="","",SUMIF($Q$7:$Q$126,D34,$Y$7:$Y$126)) -> 18 | M34: =IF(D34="","",IF(J34="Ja",K34,G34)) -> 79000 | N34: =IF(D34="","",IF(J34="Ja",L34,H34)) -> 18 | O34: Läktare 40–80 m², före tillgänglighetsmultiplikator. | W34: =IF(OR(T34="",V34=""),0,T34*V34) -> 0 | Y34: =IF(OR(T34="",X34=""),0,T34*X34) -> 0 | Z34: =IF(Inställningar!$B$5="",0,Inställningar!$B$5) -> 850 | AA34: =Y34*Z34 -> 0 | AC34: =IF(Inställningar!$B$6="",0,Inställningar!$B$6) -> 0.15 | AD34: =ROUND((W34+AA34+IF(AB34="",0,AB34))*(1+AC34),0) -> 0
A35: Ja | B35: stands | C35: quote | D35: stands:quote | E35: Läktare grundpaket | F35: Offert | G35: 0 | H35: 0 | I35: Ja | J35: Nej | K35: =IF(D35="","",SUMIF($Q$7:$Q$126,D35,$AD$7:$AD$126)) -> 0 | L35: =IF(D35="","",SUMIF($Q$7:$Q$126,D35,$Y$7:$Y$126)) -> 0 | M35: =IF(D35="","",IF(J35="Ja",K35,G35)) -> 0 | N35: =IF(D35="","",IF(J35="Ja",L35,H35)) -> 0 | O35: Större än 80 m² kräver offert. | W35: =IF(OR(T35="",V35=""),0,T35*V35) -> 0 | Y35: =IF(OR(T35="",X35=""),0,T35*X35) -> 0 | Z35: =IF(Inställningar!$B$5="",0,Inställningar!$B$5) -> 850 | AA35: =Y35*Z35 -> 0 | AC35: =IF(Inställningar!$B$6="",0,Inställningar!$B$6) -> 0.15 | AD35: =ROUND((W35+AA35+IF(AB35="",0,AB35))*(1+AC35),0) -> 0
A36: Ja | B36: checks | C36: ab04 | D36: checks:ab04 | E36: Entreprenad, dokumentation och krav | F36: Regel | G36: 0 | H36: 0 | I36: Nej | J36: Nej | K36: =IF(D36="","",SUMIF($Q$7:$Q$126,D36,$AD$7:$AD$126)) -> 0 | L36: =IF(D36="","",SUMIF($Q$7:$Q$126,D36,$Y$7:$Y$126)) -> 0 | M36: =IF(D36="","",IF(J36="Ja",K36,G36)) -> 0 | N36: =IF(D36="","",IF(J36="Ja",L36,H36)) -> 0 | O36: AB 04 markerat. | W36: =IF(OR(T36="",V36=""),0,T36*V36) -> 0 | Y36: =IF(OR(T36="",X36=""),0,T36*X36) -> 0 | Z36: =IF(Inställningar!$B$5="",0,Inställningar!$B$5) -> 850 | AA36: =Y36*Z36 -> 0 | AC36: =IF(Inställningar!$B$6="",0,Inställningar!$B$6) -> 0.15 | AD36: =ROUND((W36+AA36+IF(AB36="",0,AB36))*(1+AC36),0) -> 0
A37: Ja | B37: checks | C37: abt06 | D37: checks:abt06 | E37: Entreprenad, dokumentation och krav | F37: Regel | G37: 0 | H37: 0 | I37: Nej | J37: Nej | K37: =IF(D37="","",SUMIF($Q$7:$Q$126,D37,$AD$7:$AD$126)) -> 0 | L37: =IF(D37="","",SUMIF($Q$7:$Q$126,D37,$Y$7:$Y$126)) -> 0 | M37: =IF(D37="","",IF(J37="Ja",K37,G37)) -> 0 | N37: =IF(D37="","",IF(J37="Ja",L37,H37)) -> 0 | O37: ABT 06 markerat. | W37: =IF(OR(T37="",V37=""),0,T37*V37) -> 0 | Y37: =IF(OR(T37="",X37=""),0,T37*X37) -> 0 | Z37: =IF(Inställningar!$B$5="",0,Inställningar!$B$5) -> 850 | AA37: =Y37*Z37 -> 0 | AC37: =IF(Inställningar!$B$6="",0,Inställningar!$B$6) -> 0.15 | AD37: =ROUND((W37+AA37+IF(AB37="",0,AB37))*(1+AC37),0) -> 0
A38: Ja | B38: checks | C38: avabInstall | D38: checks:avabInstall | E38: Entreprenad, dokumentation och krav | F38: Regel | G38: 0 | H38: 0 | I38: Nej | J38: Nej | K38: =IF(D38="","",SUMIF($Q$7:$Q$126,D38,$AD$7:$AD$126)) -> 0 | L38: =IF(D38="","",SUMIF($Q$7:$Q$126,D38,$Y$7:$Y$126)) -> 0 | M38: =IF(D38="","",IF(J38="Ja",K38,G38)) -> 0 | N38: =IF(D38="","",IF(J38="Ja",L38,H38)) -> 0 | O38: AVAB installerar allt. | W38: =IF(OR(T38="",V38=""),0,T38*V38) -> 0 | Y38: =IF(OR(T38="",X38=""),0,T38*X38) -> 0 | Z38: =IF(Inställningar!$B$5="",0,Inställningar!$B$5) -> 850 | AA38: =Y38*Z38 -> 0 | AC38: =IF(Inställningar!$B$6="",0,Inställningar!$B$6) -> 0.15 | AD38: =ROUND((W38+AA38+IF(AB38="",0,AB38))*(1+AC38),0) -> 0
A39: Ja | B39: checks | C39: electricianInstall | D39: checks:electricianInstall | E39: Entreprenad, dokumentation och krav | F39: Regel | G39: 0 | H39: 0 | I39: Nej | J39: Nej | K39: =IF(D39="","",SUMIF($Q$7:$Q$126,D39,$AD$7:$AD$126)) -> 0 | L39: =IF(D39="","",SUMIF($Q$7:$Q$126,D39,$Y$7:$Y$126)) -> 0 | M39: =IF(D39="","",IF(J39="Ja",K39,G39)) -> 0 | N39: =IF(D39="","",IF(J39="Ja",L39,H39)) -> 0 | O39: Elektriker installerar efter AVAB:s ritning. | W39: =IF(OR(T39="",V39=""),0,T39*V39) -> 0 | Y39: =IF(OR(T39="",X39=""),0,T39*X39) -> 0 | Z39: =IF(Inställningar!$B$5="",0,Inställningar!$B$5) -> 850 | AA39: =Y39*Z39 -> 0 | AC39: =IF(Inställningar!$B$6="",0,Inställningar!$B$6) -> 0.15 | AD39: =ROUND((W39+AA39+IF(AB39="",0,AB39))*(1+AC39),0) -> 0
A40: Ja | B40: checks | C40: documentation | D40: checks:documentation | E40: Entreprenad, dokumentation och krav | F40: Fast | G40: 12000 | H40: 4 | I40: Nej | J40: Ja | K40: =IF(D40="","",SUMIF($Q$7:$Q$126,D40,$AD$7:$AD$126)) -> 12000 | L40: =IF(D40="","",SUMIF($Q$7:$Q$126,D40,$Y$7:$Y$126)) -> 4 | M40: =IF(D40="","",IF(J40="Ja",K40,G40)) -> 12000 | N40: =IF(D40="","",IF(J40="Ja",L40,H40)) -> 4 | O40: Relationshandling och dokumentation. | W40: =IF(OR(T40="",V40=""),0,T40*V40) -> 0 | Y40: =IF(OR(T40="",X40=""),0,T40*X40) -> 0 | Z40: =IF(Inställningar!$B$5="",0,Inställningar!$B$5) -> 850 | AA40: =Y40*Z40 -> 0 | AC40: =IF(Inställningar!$B$6="",0,Inställningar!$B$6) -> 0.15 | AD40: =ROUND((W40+AA40+IF(AB40="",0,AB40))*(1+AC40),0) -> 0
... A43: Ja | B43: checks | C43: warranty5 | D43: checks:warranty5 | E43: Garanti och materialhantering | F43: Procent | G43: 0 | H43: 0 | I43: Nej | J43: Nej | K43: =IF(D43="","",SUMIF($Q$7:$Q$126,D43,$AD$7:$AD$126)) -> 0 | L43: =IF(D43="","",SUMIF($Q$7:$Q$126,D43,$Y$7:$Y$126)) -> 0 | M43: =IF(D43="","",IF(J43="Ja",K43,G43)) -> 0 | N43: =IF(D43="","",IF(J43="Ja",L43,H43)) -> 0 | O43: 5 års garantitid. 10 % påslag på subtotal i nuvarande HTML-logik. | W43: =IF(OR(T43="",V43=""),0,T43*V43) -> 0 | Y43: =IF(OR(T43="",X43=""),0,T43*X43) -> 0 | Z43: =IF(Inställningar!$B$5="",0,Inställningar!$B$5) -> 850 | AA43: =Y43*Z43 -> 0 | AC43: =IF(Inställningar!$B$6="",0,Inställningar!$B$6) -> 0.15 | AD43: =ROUND((W43+AA43+IF(AB43="",0,AB43))*(1+AC43),0) -> 0
A44: Nej | I44: Nej | J44: Nej | K44: =IF(D44="","",SUMIF($Q$7:$Q$126,D44,$AD$7:$AD$126)) | L44: =IF(D44="","",SUMIF($Q$7:$Q$126,D44,$Y$7:$Y$126)) | M44: =IF(D44="","",IF(J44="Ja",K44,G44)) | N44: =IF(D44="","",IF(J44="Ja",L44,H44)) | W44: =IF(OR(T44="",V44=""),0,T44*V44) -> 0 | Y44: =IF(OR(T44="",X44=""),0,T44*X44) -> 0 | Z44: =IF(Inställningar!$B$5="",0,Inställningar!$B$5) -> 850 | AA44: =Y44*Z44 -> 0 | AC44: =IF(Inställningar!$B$6="",0,Inställningar!$B$6) -> 0.15 | AD44: =ROUND((W44+AA44+IF(AB44="",0,AB44))*(1+AC44),0) -> 0
A45: Nej | I45: Nej | J45: Nej | K45: =IF(D45="","",SUMIF($Q$7:$Q$126,D45,$AD$7:$AD$126)) | L45: =IF(D45="","",SUMIF($Q$7:$Q$126,D45,$Y$7:$Y$126)) | M45: =IF(D45="","",IF(J45="Ja",K45,G45)) | N45: =IF(D45="","",IF(J45="Ja",L45,H45)) | W45: =IF(OR(T45="",V45=""),0,T45*V45) -> 0 | Y45: =IF(OR(T45="",X45=""),0,T45*X45) -> 0 | Z45: =IF(Inställningar!$B$5="",0,Inställningar!$B$5) -> 850 | AA45: =Y45*Z45 -> 0 | AC45: =IF(Inställningar!$B$6="",0,Inställningar!$B$6) -> 0.15 | AD45: =ROUND((W45+AA45+IF(AB45="",0,AB45))*(1+AC45),0) -> 0
...

Sheet Simhall
A1: Simhall – kalkylmaster
A3: TESTSTART – värden är inlagda för provkörning och är inte skarpa offerter. Byt dem innan publicering. Vänster: webbpaket. Höger: interna startdelar.
A6: Publicera | B6: Grupp | C6: Nyckel | D6: Paket-ID | E6: Visningsnamn | F6: Typ | G6: Nuvarande webbpris | H6: Nuvarande timmar | I6: Offert? | J6: Använd intern kalkyl? | K6: Internt kalkylpris | L6: Interna timmar | M6: Exportpris | N6: Exporttimmar | O6: Notering | Q6: Paket-ID | R6: Del-ID | S6: Benämning | T6: Antal | U6: Enhet | V6: Inköpspris/st | W6: Material | X6: Arbete h/st | Y6: Timmar | Z6: Timpris | AA6: Arbete | AB6: Övrigt | AC6: Påslag % | AD6: Budgetpris | AE6: Kommentar
A7: Ja | B7: facilityType | C7: standard | D7: facilityType:standard | E7: Simhall – grundlogik | F7: Fast | G7: 0 | H7: 0 | I7: Nej | J7: Nej | K7: =IF(D7="","",SUMIF($Q$7:$Q$126,D7,$AD$7:$AD$126)) -> 0 | L7: =IF(D7="","",SUMIF($Q$7:$Q$126,D7,$Y$7:$Y$126)) -> 0 | M7: =IF(D7="","",IF(J7="Ja",K7,G7)) -> 0 | N7: =IF(D7="","",IF(J7="Ja",L7,H7)) -> 0 | O7: Standard simhall. TESTSTARTVÄRDE. | Q7: facilityType:multi | R7: START-multi | S7: Startmaterial / ersätt med verklig delkalkyl | T7: 1 | U7: paket | V7: 13991.304 | W7: =IF(OR(T7="",V7=""),0,T7*V7) -> 13991.304 | X7: 4 | Y7: =IF(OR(T7="",X7=""),0,T7*X7) -> 4 | Z7: =IF(Inställningar!$B$5="",0,Inställningar!$B$5) -> 850 | AA7: =Y7*Z7 -> 3400 | AB7: 0 | AC7: =IF(Inställningar!$B$6="",0,Inställningar!$B$6) -> 0.15 | AD7: =ROUND((W7+AA7+IF(AB7="",0,AB7))*(1+AC7),0) -> 20000 | AE7: TESTSTARTVÄRDE. Generisk startfördelning för test; byt mot verkliga komponenter.
A8: Ja | B8: facilityType | C8: multi | D8: facilityType:multi | E8: Simhall – grundlogik | F8: Fast | G8: 20000 | H8: 4 | I8: Nej | J8: Ja | K8: =IF(D8="","",SUMIF($Q$7:$Q$126,D8,$AD$7:$AD$126)) -> 20000 | L8: =IF(D8="","",SUMIF($Q$7:$Q$126,D8,$Y$7:$Y$126)) -> 4 | M8: =IF(D8="","",IF(J8="Ja",K8,G8)) -> 20000 | N8: =IF(D8="","",IF(J8="Ja",L8,H8)) -> 4 | O8: Flera bassänger/zoner. TESTSTARTVÄRDE – byt innan publicering. | Q8: basePackage:standard | R8: START-standard | S8: Startmaterial / ersätt med verklig delkalkyl | T8: 1 | U8: paket | V8: 95291.304 | W8: =IF(OR(T8="",V8=""),0,T8*V8) -> 95291.304 | X8: 26 | Y8: =IF(OR(T8="",X8=""),0,T8*X8) -> 26 | Z8: =IF(Inställningar!$B$5="",0,Inställningar!$B$5) -> 850 | AA8: =Y8*Z8 -> 22100 | AB8: 0 | AC8: =IF(Inställningar!$B$6="",0,Inställningar!$B$6) -> 0.15 | AD8: =ROUND((W8+AA8+IF(AB8="",0,AB8))*(1+AC8),0) -> 135000 | AE8: TESTSTARTVÄRDE. Generisk startfördelning för test; byt mot verkliga komponenter.
A9: Ja | B9: basePackage | C9: standard | D9: basePackage:standard | E9: Basljud simhall | F9: Fast | G9: 135000 | H9: 26 | I9: Nej | J9: Ja | K9: =IF(D9="","",SUMIF($Q$7:$Q$126,D9,$AD$7:$AD$126)) -> 135000 | L9: =IF(D9="","",SUMIF($Q$7:$Q$126,D9,$Y$7:$Y$126)) -> 26 | M9: =IF(D9="","",IF(J9="Ja",K9,G9)) -> 135000 | N9: =IF(D9="","",IF(J9="Ja",L9,H9)) -> 26 | O9: Grundpaket för simhallsmiljö. TESTSTARTVÄRDE. | Q9: basePackage:dsp | R9: START-dsp | S9: Startmaterial / ersätt med verklig delkalkyl | T9: 1 | U9: paket | V9: 116278.26 | W9: =IF(OR(T9="",V9=""),0,T9*V9) -> 116278.26 | X9: 32 | Y9: =IF(OR(T9="",X9=""),0,T9*X9) -> 32 | Z9: =IF(Inställningar!$B$5="",0,Inställningar!$B$5) -> 850 | AA9: =Y9*Z9 -> 27200 | AB9: 0 | AC9: =IF(Inställningar!$B$6="",0,Inställningar!$B$6) -> 0.15 | AD9: =ROUND((W9+AA9+IF(AB9="",0,AB9))*(1+AC9),0) -> 165000 | AE9: TESTSTARTVÄRDE. Generisk startfördelning för test; byt mot verkliga komponenter.
A10: Ja | B10: basePackage | C10: dsp | D10: basePackage:dsp | E10: Basljud simhall med DSP | F10: Fast | G10: 165000 | H10: 32 | I10: Nej | J10: Ja | K10: =IF(D10="","",SUMIF($Q$7:$Q$126,D10,$AD$7:$AD$126)) -> 165000 | L10: =IF(D10="","",SUMIF($Q$7:$Q$126,D10,$Y$7:$Y$126)) -> 32 | M10: =IF(D10="","",IF(J10="Ja",K10,G10)) -> 165000 | N10: =IF(D10="","",IF(J10="Ja",L10,H10)) -> 32 | O10: Fler zoner och styrlogik. TESTSTARTVÄRDE. | Q10: control:knob | R10: START-knob | S10: Startmaterial / ersätt med verklig delkalkyl | T10: 1 | U10: paket | V10: 4821.7391 | W10: =IF(OR(T10="",V10=""),0,T10*V10) -> 4821.7391 | X10: 2 | Y10: =IF(OR(T10="",X10=""),0,T10*X10) -> 2 | Z10: =IF(Inställningar!$B$5="",0,Inställningar!$B$5) -> 850 | AA10: =Y10*Z10 -> 1700 | AB10: 0 | AC10: =IF(Inställningar!$B$6="",0,Inställningar!$B$6) -> 0.15 | AD10: =ROUND((W10+AA10+IF(AB10="",0,AB10))*(1+AC10),0) -> 7500 | AE10: TESTSTARTVÄRDE. Generisk startfördelning för test; byt mot verkliga komponenter.
A11: Ja | B11: control | C11: knob | D11: control:knob | E11: Styrning | F11: Fast | G11: 7500 | H11: 2 | I11: Nej | J11: Ja | K11: =IF(D11="","",SUMIF($Q$7:$Q$126,D11,$AD$7:$AD$126)) -> 7500 | L11: =IF(D11="","",SUMIF($Q$7:$Q$126,D11,$Y$7:$Y$126)) -> 2 | M11: =IF(D11="","",IF(J11="Ja",K11,G11)) -> 7500 | N11: =IF(D11="","",IF(J11="Ja",L11,H11)) -> 2 | O11: Enkel styrning. TESTSTARTVÄRDE. | Q11: control:touch | R11: START-touch | S11: Startmaterial / ersätt med verklig delkalkyl | T11: 1 | U11: paket | V11: 22726.087 | W11: =IF(OR(T11="",V11=""),0,T11*V11) -> 22726.087 | X11: 6 | Y11: =IF(OR(T11="",X11=""),0,T11*X11) -> 6 | Z11: =IF(Inställningar!$B$5="",0,Inställningar!$B$5) -> 850 | AA11: =Y11*Z11 -> 5100 | AB11: 0 | AC11: =IF(Inställningar!$B$6="",0,Inställningar!$B$6) -> 0.15 | AD11: =ROUND((W11+AA11+IF(AB11="",0,AB11))*(1+AC11),0) -> 32000 | AE11: TESTSTARTVÄRDE. Generisk startfördelning för test; byt mot verkliga komponenter.
A12: Ja | B12: control | C12: touch | D12: control:touch | E12: Styrning | F12: Fast | G12: 32000 | H12: 6 | I12: Nej | J12: Ja | K12: =IF(D12="","",SUMIF($Q$7:$Q$126,D12,$AD$7:$AD$126)) -> 32000 | L12: =IF(D12="","",SUMIF($Q$7:$Q$126,D12,$Y$7:$Y$126)) -> 6 | M12: =IF(D12="","",IF(J12="Ja",K12,G12)) -> 32000 | N12: =IF(D12="","",IF(J12="Ja",L12,H12)) -> 6 | O12: Touchstyrning och zonlägen. TESTSTARTVÄRDE. | Q12: accessibility:loopStandard | R12: START-loopStandard | S12: Startmaterial / ersätt med verklig delkalkyl | T12: 1 | U12: paket | V12: 109478.26 | W12: =IF(OR(T12="",V12=""),0,T12*V12) -> 109478.26 | X12: 40 | Y12: =IF(OR(T12="",X12=""),0,T12*X12) -> 40 | Z12: =IF(Inställningar!$B$5="",0,Inställningar!$B$5) -> 850 | AA12: =Y12*Z12 -> 34000 | AB12: 0 | AC12: =IF(Inställningar!$B$6="",0,Inställningar!$B$6) -> 0.15 | AD12: =ROUND((W12+AA12+IF(AB12="",0,AB12))*(1+AC12),0) -> 165000 | AE12: TESTSTARTVÄRDE. Generisk startfördelning för test; byt mot verkliga komponenter.
A13: Ja | B13: accessibility | C13: loopStandard | D13: accessibility:loopStandard | E13: Hörslinga simhall | F13: Fast | G13: 165000 | H13: 40 | I13: Nej | J13: Ja | K13: =IF(D13="","",SUMIF($Q$7:$Q$126,D13,$AD$7:$AD$126)) -> 165000 | L13: =IF(D13="","",SUMIF($Q$7:$Q$126,D13,$Y$7:$Y$126)) -> 40 | M13: =IF(D13="","",IF(J13="Ja",K13,G13)) -> 165000 | N13: =IF(D13="","",IF(J13="Ja",L13,H13)) -> 40 | O13: Standardiserat testvärde för tillgänglighet. | Q13: accessibility:auracast | R13: START-auracast | S13: Startmaterial / ersätt med verklig delkalkyl | T13: 1 | U13: paket | V13: 29663.043 | W13: =IF(OR(T13="",V13=""),0,T13*V13) -> 29663.043 | X13: 5 | Y13: =IF(OR(T13="",X13=""),0,T13*X13) -> 5 | Z13: =IF(Inställningar!$B$5="",0,Inställningar!$B$5) -> 850 | AA13: =Y13*Z13 -> 4250 | AB13: 0 | AC13: =IF(Inställningar!$B$6="",0,Inställningar!$B$6) -> 0.15 | AD13: =ROUND((W13+AA13+IF(AB13="",0,AB13))*(1+AC13),0) -> 39000 | AE13: TESTSTARTVÄRDE. Generisk startfördelning för test; byt mot verkliga komponenter.
A14: Ja | B14: accessibility | C14: auracast | D14: accessibility:auracast | E14: Auracast | F14: Fast | G14: 39000 | H14: 5 | I14: Nej | J14: Ja | K14: =IF(D14="","",SUMIF($Q$7:$Q$126,D14,$AD$7:$AD$126)) -> 39000 | L14: =IF(D14="","",SUMIF($Q$7:$Q$126,D14,$Y$7:$Y$126)) -> 5 | M14: =IF(D14="","",IF(J14="Ja",K14,G14)) -> 39000 | N14: =IF(D14="","",IF(J14="Ja",L14,H14)) -> 5 | O14: Kompletterande ljuddistribution. TESTSTARTVÄRDE. | Q14: sti:050 | R14: START-050 | S14: Startmaterial / ersätt med verklig delkalkyl | T14: 1 | U14: paket | V14: 17547.826 | W14: =IF(OR(T14="",V14=""),0,T14*V14) -> 17547.826 | X14: 8 | Y14: =IF(OR(T14="",X14=""),0,T14*X14) -> 8 | Z14: =IF(Inställningar!$B$5="",0,Inställningar!$B$5) -> 850 | AA14: =Y14*Z14 -> 6800 | AB14: 0 | AC14: =IF(Inställningar!$B$6="",0,Inställningar!$B$6) -> 0.15 | AD14: =ROUND((W14+AA14+IF(AB14="",0,AB14))*(1+AC14),0) -> 28000 | AE14: TESTSTARTVÄRDE. Generisk startfördelning för test; byt mot verkliga komponenter.
A15: Ja | B15: sti | C15: 050 | D15: sti:050 | E15: STI och inmätning | F15: Fast | G15: 28000 | H15: 8 | I15: Nej | J15: Ja | K15: =IF(D15="","",SUMIF($Q$7:$Q$126,D15,$AD$7:$AD$126)) -> 28000 | L15: =IF(D15="","",SUMIF($Q$7:$Q$126,D15,$Y$7:$Y$126)) -> 8 | M15: =IF(D15="","",IF(J15="Ja",K15,G15)) -> 28000 | N15: =IF(D15="","",IF(J15="Ja",L15,H15)) -> 8 | O15: STI 0,50. TESTSTARTVÄRDE. | Q15: sti:060 | R15: START-060 | S15: Startmaterial / ersätt med verklig delkalkyl | T15: 1 | U15: paket | V15: 28930.435 | W15: =IF(OR(T15="",V15=""),0,T15*V15) -> 28930.435 | X15: 12 | Y15: =IF(OR(T15="",X15=""),0,T15*X15) -> 12 | Z15: =IF(Inställningar!$B$5="",0,Inställningar!$B$5) -> 850 | AA15: =Y15*Z15 -> 10200 | AB15: 0 | AC15: =IF(Inställningar!$B$6="",0,Inställningar!$B$6) -> 0.15 | AD15: =ROUND((W15+AA15+IF(AB15="",0,AB15))*(1+AC15),0) -> 45000 | AE15: TESTSTARTVÄRDE. Generisk startfördelning för test; byt mot verkliga komponenter.
A16: Ja | B16: sti | C16: 060 | D16: sti:060 | E16: STI och inmätning | F16: Fast | G16: 45000 | H16: 12 | I16: Nej | J16: Ja | K16: =IF(D16="","",SUMIF($Q$7:$Q$126,D16,$AD$7:$AD$126)) -> 45000 | L16: =IF(D16="","",SUMIF($Q$7:$Q$126,D16,$Y$7:$Y$126)) -> 12 | M16: =IF(D16="","",IF(J16="Ja",K16,G16)) -> 45000 | N16: =IF(D16="","",IF(J16="Ja",L16,H16)) -> 12 | O16: STI 0,60. TESTSTARTVÄRDE. | Q16: unit:handMic | R16: START-handMic | S16: Startmaterial / ersätt med verklig delkalkyl | T16: 1 | U16: paket | V16: 6705.4348 | W16: =IF(OR(T16="",V16=""),0,T16*V16) -> 6705.4348 | X16: 0.5 | Y16: =IF(OR(T16="",X16=""),0,T16*X16) -> 0.5 | Z16: =IF(Inställningar!$B$5="",0,Inställningar!$B$5) -> 850 | AA16: =Y16*Z16 -> 425 | AB16: 0 | AC16: =IF(Inställningar!$B$6="",0,Inställningar!$B$6) -> 0.15 | AD16: =ROUND((W16+AA16+IF(AB16="",0,AB16))*(1+AC16),0) -> 8200 | AE16: TESTSTARTVÄRDE. Generisk startfördelning för test; byt mot verkliga komponenter.
A17: Ja | B17: unit | C17: handMic | D17: unit:handMic | E17: Mikrofoner och anslutning | F17: Enhet | G17: 8200 | H17: 0.5 | I17: Nej | J17: Ja | K17: =IF(D17="","",SUMIF($Q$7:$Q$126,D17,$AD$7:$AD$126)) -> 8200 | L17: =IF(D17="","",SUMIF($Q$7:$Q$126,D17,$Y$7:$Y$126)) -> 0.5 | M17: =IF(D17="","",IF(J17="Ja",K17,G17)) -> 8200 | N17: =IF(D17="","",IF(J17="Ja",L17,H17)) -> 0.5 | O17: Trådlös handmikrofon. TESTSTARTVÄRDE. | Q17: unit:headset | R17: START-headset | S17: Startmaterial / ersätt med verklig delkalkyl | T17: 1 | U17: paket | V17: 7835.8696 | W17: =IF(OR(T17="",V17=""),0,T17*V17) -> 7835.8696 | X17: 0.5 | Y17: =IF(OR(T17="",X17=""),0,T17*X17) -> 0.5 | Z17: =IF(Inställningar!$B$5="",0,Inställningar!$B$5) -> 850 | AA17: =Y17*Z17 -> 425 | AB17: 0 | AC17: =IF(Inställningar!$B$6="",0,Inställningar!$B$6) -> 0.15 | AD17: =ROUND((W17+AA17+IF(AB17="",0,AB17))*(1+AC17),0) -> 9500 | AE17: TESTSTARTVÄRDE. Generisk startfördelning för test; byt mot verkliga komponenter.
A18: Ja | B18: unit | C18: headset | D18: unit:headset | E18: Mikrofoner och anslutning | F18: Enhet | G18: 9500 | H18: 0.5 | I18: Nej | J18: Ja | K18: =IF(D18="","",SUMIF($Q$7:$Q$126,D18,$AD$7:$AD$126)) -> 9500 | L18: =IF(D18="","",SUMIF($Q$7:$Q$126,D18,$Y$7:$Y$126)) -> 0.5 | M18: =IF(D18="","",IF(J18="Ja",K18,G18)) -> 9500 | N18: =IF(D18="","",IF(J18="Ja",L18,H18)) -> 0.5 | O18: Trådlöst headset. TESTSTARTVÄRDE. | Q18: unit:bluetooth | R18: START-bluetooth | S18: Startmaterial / ersätt med verklig delkalkyl | T18: 1 | U18: paket | V18: 3488.0435 | W18: =IF(OR(T18="",V18=""),0,T18*V18) -> 3488.0435 | X18: 0.5 | Y18: =IF(OR(T18="",X18=""),0,T18*X18) -> 0.5 | Z18: =IF(Inställningar!$B$5="",0,Inställningar!$B$5) -> 850 | AA18: =Y18*Z18 -> 425 | AB18: 0 | AC18: =IF(Inställningar!$B$6="",0,Inställningar!$B$6) -> 0.15 | AD18: =ROUND((W18+AA18+IF(AB18="",0,AB18))*(1+AC18),0) -> 4500 | AE18: TESTSTARTVÄRDE. Generisk startfördelning för test; byt mot verkliga komponenter.
... A24: Ja | B24: display | C24: projector | D24: display:projector | E24: Projektor/bild i multihall | F24: Fast | G24: 65000 | H24: 8 | I24: Nej | J24: Ja | K24: =IF(D24="","",SUMIF($Q$7:$Q$126,D24,$AD$7:$AD$126)) -> 65000 | L24: =IF(D24="","",SUMIF($Q$7:$Q$126,D24,$Y$7:$Y$126)) -> 8 | M24: =IF(D24="","",IF(J24="Ja",K24,G24)) -> 65000 | N24: =IF(D24="","",IF(J24="Ja",L24,H24)) -> 8 | O24: Projektor/bildlösning. TESTSTARTVÄRDE. | Q24: checks:documentation | R24: START-documentation | S24: Startmaterial / ersätt med verklig delkalkyl | T24: 1 | U24: paket | V24: 8773.913 | W24: =IF(OR(T24="",V24=""),0,T24*V24) -> 8773.913 | X24: 4 | Y24: =IF(OR(T24="",X24=""),0,T24*X24) -> 4 | Z24: =IF(Inställningar!$B$5="",0,Inställningar!$B$5) -> 850 | AA24: =Y24*Z24 -> 3400 | AB24: 0 | AC24: =IF(Inställningar!$B$6="",0,Inställningar!$B$6) -> 0.15 | AD24: =ROUND((W24+AA24+IF(AB24="",0,AB24))*(1+AC24),0) -> 14000 | AE24: TESTSTARTVÄRDE. Generisk startfördelning för test; byt mot verkliga komponenter.
A25: Ja | B25: checks | C25: documentation | D25: checks:documentation | E25: Relationshandling och dokumentation | F25: Fast | G25: 14000 | H25: 4 | I25: Nej | J25: Ja | K25: =IF(D25="","",SUMIF($Q$7:$Q$126,D25,$AD$7:$AD$126)) -> 14000 | L25: =IF(D25="","",SUMIF($Q$7:$Q$126,D25,$Y$7:$Y$126)) -> 4 | M25: =IF(D25="","",IF(J25="Ja",K25,G25)) -> 14000 | N25: =IF(D25="","",IF(J25="Ja",L25,H25)) -> 4 | O25: TESTSTARTVÄRDE. | W25: =IF(OR(T25="",V25=""),0,T25*V25) -> 0 | Y25: =IF(OR(T25="",X25=""),0,T25*X25) -> 0 | Z25: =IF(Inställningar!$B$5="",0,Inställningar!$B$5) -> 850 | AA25: =Y25*Z25 -> 0 | AC25: =IF(Inställningar!$B$6="",0,Inställningar!$B$6) -> 0.15 | AD25: =ROUND((W25+AA25+IF(AB25="",0,AB25))*(1+AC25),0) -> 0
A26: Ja | B26: checks | C26: fireAlarm | D26: checks:fireAlarm | E26: Brandlarm tystar ljud | F26: Regel | G26: 0 | H26: 0 | I26: Nej | J26: Nej | K26: =IF(D26="","",SUMIF($Q$7:$Q$126,D26,$AD$7:$AD$126)) -> 0 | L26: =IF(D26="","",SUMIF($Q$7:$Q$126,D26,$Y$7:$Y$126)) -> 0 | M26: =IF(D26="","",IF(J26="Ja",K26,G26)) -> 0 | N26: =IF(D26="","",IF(J26="Ja",L26,H26)) -> 0 | O26: Funktionsregel – inget separat startpris. | W26: =IF(OR(T26="",V26=""),0,T26*V26) -> 0 | Y26: =IF(OR(T26="",X26=""),0,T26*X26) -> 0 | Z26: =IF(Inställningar!$B$5="",0,Inställningar!$B$5) -> 850 | AA26: =Y26*Z26 -> 0 | AC26: =IF(Inställningar!$B$6="",0,Inställningar!$B$6) -> 0.15 | AD26: =ROUND((W26+AA26+IF(AB26="",0,AB26))*(1+AC26),0) -> 0
A27: Ja | B27: checks | C27: quoteSystems | D27: checks:quoteSystems | E27: Talat utrymningslarm | F27: Offert | G27: 0 | H27: 0 | I27: Ja | J27: Nej | K27: =IF(D27="","",SUMIF($Q$7:$Q$126,D27,$AD$7:$AD$126)) -> 0 | L27: =IF(D27="","",SUMIF($Q$7:$Q$126,D27,$Y$7:$Y$126)) -> 0 | M27: =IF(D27="","",IF(J27="Ja",K27,G27)) -> 0 | N27: =IF(D27="","",IF(J27="Ja",L27,H27)) -> 0 | O27: Separat projektering/offert. | W27: =IF(OR(T27="",V27=""),0,T27*V27) -> 0 | Y27: =IF(OR(T27="",X27=""),0,T27*X27) -> 0 | Z27: =IF(Inställningar!$B$5="",0,Inställningar!$B$5) -> 850 | AA27: =Y27*Z27 -> 0 | AC27: =IF(Inställningar!$B$6="",0,Inställningar!$B$6) -> 0.15 | AD27: =ROUND((W27+AA27+IF(AB27="",0,AB27))*(1+AC27),0) -> 0
A28: Ja | B28: checks | C28: warranty5 | D28: checks:warranty5 | E28: Garanti och materialhantering | F28: Procent | G28: 0 | H28: 0 | I28: Nej | J28: Nej | K28: =IF(D28="","",SUMIF($Q$7:$Q$126,D28,$AD$7:$AD$126)) -> 0 | L28: =IF(D28="","",SUMIF($Q$7:$Q$126,D28,$Y$7:$Y$126)) -> 0 | M28: =IF(D28="","",IF(J28="Ja",K28,G28)) -> 0 | N28: =IF(D28="","",IF(J28="Ja",L28,H28)) -> 0 | O28: 10 % på subtotal som testregel. | W28: =IF(OR(T28="",V28=""),0,T28*V28) -> 0 | Y28: =IF(OR(T28="",X28=""),0,T28*X28) -> 0 | Z28: =IF(Inställningar!$B$5="",0,Inställningar!$B$5) -> 850 | AA28: =Y28*Z28 -> 0 | AC28: =IF(Inställningar!$B$6="",0,Inställningar!$B$6) -> 0.15 | AD28: =ROUND((W28+AA28+IF(AB28="",0,AB28))*(1+AC28),0) -> 0
A29: Nej | I29: Nej | J29: Nej | K29: =IF(D29="","",SUMIF($Q$7:$Q$126,D29,$AD$7:$AD$126)) | L29: =IF(D29="","",SUMIF($Q$7:$Q$126,D29,$Y$7:$Y$126)) | M29: =IF(D29="","",IF(J29="Ja",K29,G29)) | N29: =IF(D29="","",IF(J29="Ja",L29,H29)) | W29: =IF(OR(T29="",V29=""),0,T29*V29) -> 0 | Y29: =IF(OR(T29="",X29=""),0,T29*X29) -> 0 | Z29: =IF(Inställningar!$B$5="",0,Inställningar!$B$5) -> 850 | AA29: =Y29*Z29 -> 0 | AC29: =IF(Inställningar!$B$6="",0,Inställningar!$B$6) -> 0.15 | AD29: =ROUND((W29+AA29+IF(AB29="",0,AB29))*(1+AC29),0) -> 0
A30: Nej | I30: Nej | J30: Nej | K30: =IF(D30="","",SUMIF($Q$7:$Q$126,D30,$AD$7:$AD$126)) | L30: =IF(D30="","",SUMIF($Q$7:$Q$126,D30,$Y$7:$Y$126)) | M30: =IF(D30="","",IF(J30="Ja",K30,G30)) | N30: =IF(D30="","",IF(J30="Ja",L30,H30)) | W30: =IF(OR(T30="",V30=""),0,T30*V30) -> 0 | Y30: =IF(OR(T30="",X30=""),0,T30*X30) -> 0 | Z30: =IF(Inställningar!$B$5="",0,Inställningar!$B$5) -> 850 | AA30: =Y30*Z30 -> 0 | AC30: =IF(Inställningar!$B$6="",0,Inställningar!$B$6) -> 0.15 | AD30: =ROUND((W30+AA30+IF(AB30="",0,AB30))*(1+AC30),0) -> 0
A31: Nej | I31: Nej | J31: Nej | K31: =IF(D31="","",SUMIF($Q$7:$Q$126,D31,$AD$7:$AD$126)) | L31: =IF(D31="","",SUMIF($Q$7:$Q$126,D31,$Y$7:$Y$126)) | M31: =IF(D31="","",IF(J31="Ja",K31,G31)) | N31: =IF(D31="","",IF(J31="Ja",L31,H31)) | W31: =IF(OR(T31="",V31=""),0,T31*V31) -> 0 | Y31: =IF(OR(T31="",X31=""),0,T31*X31) -> 0 | Z31: =IF(Inställningar!$B$5="",0,Inställningar!$B$5) -> 850 | AA31: =Y31*Z31 -> 0 | AC31: =IF(Inställningar!$B$6="",0,Inställningar!$B$6) -> 0.15 | AD31: =ROUND((W31+AA31+IF(AB31="",0,AB31))*(1+AC31),0) -> 0
A32: Nej | I32: Nej | J32: Nej | K32: =IF(D32="","",SUMIF($Q$7:$Q$126,D32,$AD$7:$AD$126)) | L32: =IF(D32="","",SUMIF($Q$7:$Q$126,D32,$Y$7:$Y$126)) | M32: =IF(D32="","",IF(J32="Ja",K32,G32)) | N32: =IF(D32="","",IF(J32="Ja",L32,H32)) | W32: =IF(OR(T32="",V32=""),0,T32*V32) -> 0 | Y32: =IF(OR(T32="",X32=""),0,T32*X32) -> 0 | Z32: =IF(Inställningar!$B$5="",0,Inställningar!$B$5) -> 850 | AA32: =Y32*Z32 -> 0 | AC32: =IF(Inställningar!$B$6="",0,Inställningar!$B$6) -> 0.15 | AD32: =ROUND((W32+AA32+IF(AB32="",0,AB32))*(1+AC32),0) -> 0
A33: Nej | I33: Nej | J33: Nej | K33: =IF(D33="","",SUMIF($Q$7:$Q$126,D33,$AD$7:$AD$126)) | L33: =IF(D33="","",SUMIF($Q$7:$Q$126,D33,$Y$7:$Y$126)) | M33: =IF(D33="","",IF(J33="Ja",K33,G33)) | N33: =IF(D33="","",IF(J33="Ja",L33,H33)) | W33: =IF(OR(T33="",V33=""),0,T33*V33) -> 0 | Y33: =IF(OR(T33="",X33=""),0,T33*X33) -> 0 | Z33: =IF(Inställningar!$B$5="",0,Inställningar!$B$5) -> 850 | AA33: =Y33*Z33 -> 0 | AC33: =IF(Inställningar!$B$6="",0,Inställningar!$B$6) -> 0.15 | AD33: =ROUND((W33+AA33+IF(AB33="",0,AB33))*(1+AC33),0) -> 0
A34: Nej | I34: Nej | J34: Nej | K34: =IF(D34="","",SUMIF($Q$7:$Q$126,D34,$AD$7:$AD$126)) | L34: =IF(D34="","",SUMIF($Q$7:$Q$126,D34,$Y$7:$Y$126)) | M34: =IF(D34="","",IF(J34="Ja",K34,G34)) | N34: =IF(D34="","",IF(J34="Ja",L34,H34)) | W34: =IF(OR(T34="",V34=""),0,T34*V34) -> 0 | Y34: =IF(OR(T34="",X34=""),0,T34*X34) -> 0 | Z34: =IF(Inställningar!$B$5="",0,Inställningar!$B$5) -> 850 | AA34: =Y34*Z34 -> 0 | AC34: =IF(Inställningar!$B$6="",0,Inställningar!$B$6) -> 0.15 | AD34: =ROUND((W34+AA34+IF(AB34="",0,AB34))*(1+AC34),0) -> 0
A35: Nej | I35: Nej | J35: Nej | K35: =IF(D35="","",SUMIF($Q$7:$Q$126,D35,$AD$7:$AD$126)) | L35: =IF(D35="","",SUMIF($Q$7:$Q$126,D35,$Y$7:$Y$126)) | M35: =IF(D35="","",IF(J35="Ja",K35,G35)) | N35: =IF(D35="","",IF(J35="Ja",L35,H35)) | W35: =IF(OR(T35="",V35=""),0,T35*V35) -> 0 | Y35: =IF(OR(T35="",X35=""),0,T35*X35) -> 0 | Z35: =IF(Inställningar!$B$5="",0,Inställningar!$B$5) -> 850 | AA35: =Y35*Z35 -> 0 | AC35: =IF(Inställningar!$B$6="",0,Inställningar!$B$6) -> 0.15 | AD35: =ROUND((W35+AA35+IF(AB35="",0,AB35))*(1+AC35),0) -> 0
A36: Nej | I36: Nej | J36: Nej | K36: =IF(D36="","",SUMIF($Q$7:$Q$126,D36,$AD$7:$AD$126)) | L36: =IF(D36="","",SUMIF($Q$7:$Q$126,D36,$Y$7:$Y$126)) | M36: =IF(D36="","",IF(J36="Ja",K36,G36)) | N36: =IF(D36="","",IF(J36="Ja",L36,H36)) | W36: =IF(OR(T36="",V36=""),0,T36*V36) -> 0 | Y36: =IF(OR(T36="",X36=""),0,T36*X36) -> 0 | Z36: =IF(Inställningar!$B$5="",0,Inställningar!$B$5) -> 850 | AA36: =Y36*Z36 -> 0 | AC36: =IF(Inställningar!$B$6="",0,Inställningar!$B$6) -> 0.15 | AD36: =ROUND((W36+AA36+IF(AB36="",0,AB36))*(1+AC36),0) -> 0
A37: Nej | I37: Nej | J37: Nej | K37: =IF(D37="","",SUMIF($Q$7:$Q$126,D37,$AD$7:$AD$126)) | L37: =IF(D37="","",SUMIF($Q$7:$Q$126,D37,$Y$7:$Y$126)) | M37: =IF(D37="","",IF(J37="Ja",K37,G37)) | N37: =IF(D37="","",IF(J37="Ja",L37,H37)) | W37: =IF(OR(T37="",V37=""),0,T37*V37) -> 0 | Y37: =IF(OR(T37="",X37=""),0,T37*X37) -> 0 | Z37: =IF(Inställningar!$B$5="",0,Inställningar!$B$5) -> 850 | AA37: =Y37*Z37 -> 0 | AC37: =IF(Inställningar!$B$6="",0,Inställningar!$B$6) -> 0.15 | AD37: =ROUND((W37+AA37+IF(AB37="",0,AB37))*(1+AC37),0) -> 0
A38: Nej | I38: Nej | J38: Nej | K38: =IF(D38="","",SUMIF($Q$7:$Q$126,D38,$AD$7:$AD$126)) | L38: =IF(D38="","",SUMIF($Q$7:$Q$126,D38,$Y$7:$Y$126)) | M38: =IF(D38="","",IF(J38="Ja",K38,G38)) | N38: =IF(D38="","",IF(J38="Ja",L38,H38)) | W38: =IF(OR(T38="",V38=""),0,T38*V38) -> 0 | Y38: =IF(OR(T38="",X38=""),0,T38*X38) -> 0 | Z38: =IF(Inställningar!$B$5="",0,Inställningar!$B$5) -> 850 | AA38: =Y38*Z38 -> 0 | AC38: =IF(Inställningar!$B$6="",0,Inställningar!$B$6) -> 0.15 | AD38: =ROUND((W38+AA38+IF(AB38="",0,AB38))*(1+AC38),0) -> 0
A39: Nej | I39: Nej | J39: Nej | K39: =IF(D39="","",SUMIF($Q$7:$Q$126,D39,$AD$7:$AD$126)) | L39: =IF(D39="","",SUMIF($Q$7:$Q$126,D39,$Y$7:$Y$126)) | M39: =IF(D39="","",IF(J39="Ja",K39,G39)) | N39: =IF(D39="","",IF(J39="Ja",L39,H39)) | W39: =IF(OR(T39="",V39=""),0,T39*V39) -> 0 | Y39: =IF(OR(T39="",X39=""),0,T39*X39) -> 0 | Z39: =IF(Inställningar!$B$5="",0,Inställningar!$B$5) -> 850 | AA39: =Y39*Z39 -> 0 | AC39: =IF(Inställningar!$B$6="",0,Inställningar!$B$6) -> 0.15 | AD39: =ROUND((W39+AA39+IF(AB39="",0,AB39))*(1+AC39),0) -> 0
A40: Nej | I40: Nej | J40: Nej | K40: =IF(D40="","",SUMIF($Q$7:$Q$126,D40,$AD$7:$AD$126)) | L40: =IF(D40="","",SUMIF($Q$7:$Q$126,D40,$Y$7:$Y$126)) | M40: =IF(D40="","",IF(J40="Ja",K40,G40)) | N40: =IF(D40="","",IF(J40="Ja",L40,H40)) | W40: =IF(OR(T40="",V40=""),0,T40*V40) -> 0 | Y40: =IF(OR(T40="",X40=""),0,T40*X40) -> 0 | Z40: =IF(Inställningar!$B$5="",0,Inställningar!$B$5) -> 850 | AA40: =Y40*Z40 -> 0 | AC40: =IF(Inställningar!$B$6="",0,Inställningar!$B$6) -> 0.15 | AD40: =ROUND((W40+AA40+IF(AB40="",0,AB40))*(1+AC40),0) -> 0
... A51: Nej | I51: Nej | J51: Nej | K51: =IF(D51="","",SUMIF($Q$7:$Q$126,D51,$AD$7:$AD$126)) | L51: =IF(D51="","",SUMIF($Q$7:$Q$126,D51,$Y$7:$Y$126)) | M51: =IF(D51="","",IF(J51="Ja",K51,G51)) | N51: =IF(D51="","",IF(J51="Ja",L51,H51)) | W51: =IF(OR(T51="",V51=""),0,T51*V51) -> 0 | Y51: =IF(OR(T51="",X51=""),0,T51*X51) -> 0 | Z51: =IF(Inställningar!$B$5="",0,Inställningar!$B$5) -> 850 | AA51: =Y51*Z51 -> 0 | AC51: =IF(Inställningar!$B$6="",0,Inställningar!$B$6) -> 0.15 | AD51: =ROUND((W51+AA51+IF(AB51="",0,AB51))*(1+AC51),0) -> 0
W52: =IF(OR(T52="",V52=""),0,T52*V52) -> 0 | Y52: =IF(OR(T52="",X52=""),0,T52*X52) -> 0 | Z52: =IF(Inställningar!$B$5="",0,Inställningar!$B$5) -> 850 | AA52: =Y52*Z52 -> 0 | AC52: =IF(Inställningar!$B$6="",0,Inställningar!$B$6) -> 0.15 | AD52: =ROUND((W52+AA52+IF(AB52="",0,AB52))*(1+AC52),0) -> 0
W53: =IF(OR(T53="",V53=""),0,T53*V53) -> 0 | Y53: =IF(OR(T53="",X53=""),0,T53*X53) -> 0 | Z53: =IF(Inställningar!$B$5="",0,Inställningar!$B$5) -> 850 | AA53: =Y53*Z53 -> 0 | AC53: =IF(Inställningar!$B$6="",0,Inställningar!$B$6) -> 0.15 | AD53: =ROUND((W53+AA53+IF(AB53="",0,AB53))*(1+AC53),0) -> 0
W54: =IF(OR(T54="",V54=""),0,T54*V54) -> 0 | Y54: =IF(OR(T54="",X54=""),0,T54*X54) -> 0 | Z54: =IF(Inställningar!$B$5="",0,Inställningar!$B$5) -> 850 | AA54: =Y54*Z54 -> 0 | AC54: =IF(Inställningar!$B$6="",0,Inställningar!$B$6) -> 0.15 | AD54: =ROUND((W54+AA54+IF(AB54="",0,AB54))*(1+AC54),0) -> 0
W55: =IF(OR(T55="",V55=""),0,T55*V55) -> 0 | Y55: =IF(OR(T55="",X55=""),0,T55*X55) -> 0 | Z55: =IF(Inställningar!$B$5="",0,Inställningar!$B$5) -> 850 | AA55: =Y55*Z55 -> 0 | AC55: =IF(Inställningar!$B$6="",0,Inställningar!$B$6) -> 0.15 | AD55: =ROUND((W55+AA55+IF(AB55="",0,AB55))*(1+AC55),0) -> 0
W56: =IF(OR(T56="",V56=""),0,T56*V56) -> 0 | Y56: =IF(OR(T56="",X56=""),0,T56*X56) -> 0 | Z56: =IF(Inställningar!$B$5="",0,Inställningar!$B$5) -> 850 | AA56: =Y56*Z56 -> 0 | AC56: =IF(Inställningar!$B$6="",0,Inställningar!$B$6) -> 0.15 | AD56: =ROUND((W56+AA56+IF(AB56="",0,AB56))*(1+AC56),0) -> 0
W57: =IF(OR(T57="",V57=""),0,T57*V57) -> 0 | Y57: =IF(OR(T57="",X57=""),0,T57*X57) -> 0 | Z57: =IF(Inställningar!$B$5="",0,Inställningar!$B$5) -> 850 | AA57: =Y57*Z57 -> 0 | AC57: =IF(Inställningar!$B$6="",0,Inställningar!$B$6) -> 0.15 | AD57: =ROUND((W57+AA57+IF(AB57="",0,AB57))*(1+AC57),0) -> 0
W58: =IF(OR(T58="",V58=""),0,T58*V58) -> 0 | Y58: =IF(OR(T58="",X58=""),0,T58*X58) -> 0 | Z58: =IF(Inställningar!$B$5="",0,Inställningar!$B$5) -> 850 | AA58: =Y58*Z58 -> 0 | AC58: =IF(Inställningar!$B$6="",0,Inställningar!$B$6) -> 0.15 | AD58: =ROUND((W58+AA58+IF(AB58="",0,AB58))*(1+AC58),0) -> 0
...

Sheet Konferens
A1: Konferens – kalkylmaster
